<?xml version="1.0" encoding="utf-8"?>
<!-- This URDF was automatically created by SolidWorks to URDF Exporter! Originally created by Stephen Brawner (brawner@gmail.com) 
     Commit Version: 1.6.0-4-g7f85cfe  Build Version: 1.6.7995.38578
     For more information, please see http://wiki.ros.org/sw_urdf_exporter -->
<robot
  name="ultron2_urdf_g">
  <link
    name="base_link">
    <inertial>
      <origin
        xyz="-3.3324E-05 0.029642 0.0004387"
        rpy="0 0 0" />
      <mass
        value="0.44235" />
      <inertia
        ixx="0.00017"
        ixy="0.00000"
        ixz="0.00000"
        iyy="0.00016"
        iyz="0.00000"
        izz="0.00017" />
    </inertial>
    <visual>
      <origin
        xyz="0 0 0"
        rpy="0 0 0" />
      <geometry>
        <mesh
          filename="package://ultron2_urdf_g/meshes/base_link.STL" />
      </geometry>
      <material
        name="">
        <color
          rgba="0.89804 0.91765 0.92941 1" />
      </material>
    </visual>
    <collision>
      <origin
        xyz="0 0 0"
        rpy="0 0 0" />
      <geometry>
        <mesh
          filename="package://ultron2_urdf_g/meshes/base_link.STL" />
      </geometry>
    </collision>
  </link>
  <link
    name="link1">
    <inertial>
      <origin
        xyz="0.025289 0.030544 -0.00031892"
        rpy="0 0 0" />
      <mass
        value="0.085583" />
      <inertia
        ixx="0.00009"
        ixy="0.00002"
        ixz="0.00000"
        iyy="0.00006"
        iyz="0.00000"
        izz="0.00009" />
    </inertial>
    <visual>
      <origin
        xyz="0 0 0"
        rpy="0 0 0" />
      <geometry>
        <mesh
          filename="package://ultron2_urdf_g/meshes/link1.STL" />
      </geometry>
      <material
        name="">
        <color
          rgba="0.89804 0.91765 0.92941 1" />
      </material>
    </visual>
    <collision>
      <origin
        xyz="0 0 0"
        rpy="0 0 0" />
      <geometry>
        <mesh
          filename="package://ultron2_urdf_g/meshes/link1.STL" />
      </geometry>
    </collision>
  </link>
  <joint
    name="joint1"
    type="revolute">
    <origin
      xyz="0 0.0605 0"
      rpy="0 0 0" />
    <parent
      link="base_link" />
    <child
      link="link1" />
    <axis
      xyz="0 1 0" />
    <limit
      lower="-10"
      upper="10"
      effort="100"
      velocity="1000" />
  </joint>
  <link
    name="link2">
    <inertial>
      <origin
        xyz="0.0297671674158853 -0.00253752324572726 -0.0263773476771438"
        rpy="0 0 0" />
      <mass
        value="1.02244259916853" />
      <inertia
        ixx="0.00146"
        ixy="0.00002"
        ixz="-0.00004"
        iyy="0.00147"
        iyz="-0.00002"
        izz="0.00069" />
    </inertial>
    <visual>
      <origin
        xyz="0 0 0"
        rpy="0 0 0" />
      <geometry>
        <mesh
          filename="package://ultron2_urdf_g/meshes/link2.STL" />
      </geometry>
      <material
        name="">
        <color
          rgba="0.898039215686275 0.917647058823529 0.929411764705882 1" />
      </material>
    </visual>
    <collision>
      <origin
        xyz="0 0 0"
        rpy="0 0 0" />
      <geometry>
        <mesh
          filename="package://ultron2_urdf_g/meshes/link2.STL" />
      </geometry>
    </collision>
  </link>
  <joint
    name="joint2"
    type="revolute">
    <origin
      xyz="0.03125 0.059 0"
      rpy="0 0 3.1416" />
    <parent
      link="link1" />
    <child
      link="link2" />
    <axis
      xyz="1 0 0" />
    <limit
      lower="-10"
      upper="10"
      effort="100"
      velocity="1000" />
  </joint>
  <link
    name="link3">
    <inertial>
      <origin
        xyz="0.000478740262498357 0.000178057733353387 0.153883622457826"
        rpy="0 0 0" />
      <mass
        value="0.84083747270065" />
      <inertia
        ixx="0.00485"
        ixy="0.00000"
        ixz="-0.00006"
        iyy="0.00491"
        iyz="0.00001"
        izz="0.00066" />
    </inertial>
    <visual>
      <origin
        xyz="0 0 0"
        rpy="0 0 0" />
      <geometry>
        <mesh
          filename="package://ultron2_urdf_g/meshes/link3.STL" />
      </geometry>
      <material
        name="">
        <color
          rgba="0.898039215686275 0.917647058823529 0.929411764705882 1" />
      </material>
    </visual>
    <collision>
      <origin
        xyz="0 0 0"
        rpy="0 0 0" />
      <geometry>
        <mesh
          filename="package://ultron2_urdf_g/meshes/link3.STL" />
      </geometry>
    </collision>
  </link>
  <joint
    name="joint3"
    type="revolute">
    <origin
      xyz="0.03125 0 -0.0905"
      rpy="3.1416 0 3.1416" />
    <parent
      link="link2" />
    <child
      link="link3" />
    <axis
      xyz="0 0 1" />
    <limit
      lower="-10"
      upper="10"
      effort="100"
      velocity="1000" />
  </joint>
  <link
    name="link4">
    <inertial>
      <origin
        xyz="0.0645117152208708 -0.0253183694781211 -9.47713628285385E-06"
        rpy="0 0 0" />
      <mass
        value="0.43314458599201" />
      <inertia
        ixx="0.00027"
        ixy="-0.00008"
        ixz="0.00000"
        iyy="0.00028"
        iyz="0.00000"
        izz="0.00036" />
    </inertial>
    <visual>
      <origin
        xyz="0 0 0"
        rpy="0 0 0" />
      <geometry>
        <mesh
          filename="package://ultron2_urdf_g/meshes/link4.STL" />
      </geometry>
      <material
        name="">
        <color
          rgba="0.752941176470588 0.752941176470588 0.752941176470588 1" />
      </material>
    </visual>
    <collision>
      <origin
        xyz="0 0 0"
        rpy="0 0 0" />
      <geometry>
        <mesh
          filename="package://ultron2_urdf_g/meshes/link4.STL" />
      </geometry>
    </collision>
  </link>
  <joint
    name="joint4"
    type="revolute">
    <origin
      xyz="0 0.03125 0.2125"
      rpy="0 0 0" />
    <parent
      link="link3" />
    <child
      link="link4" />
    <axis
      xyz="0 1 0" />
    <limit
      lower="-10"
      upper="10"
      effort="100"
      velocity="1000" />
  </joint>
  <link
    name="link5">
    <inertial>
      <origin
        xyz="0.0529216791044983 -0.00827331453644387 -6.09364502447973E-05"
        rpy="0 0 0" />
      <mass
        value="0.552346497691693" />
      <inertia
        ixx="0.00049"
        ixy="-0.00002"
        ixz="0.00000"
        iyy="0.00091"
        iyz="0.00000"
        izz="0.00098" />
    </inertial>
    <visual>
      <origin
        xyz="0 0 0"
        rpy="0 0 0" />
      <geometry>
        <mesh
          filename="package://ultron2_urdf_g/meshes/link5.STL" />
      </geometry>
      <material
        name="">
        <color
          rgba="0.898039215686275 0.917647058823529 0.929411764705882 1" />
      </material>
    </visual>
    <collision>
      <origin
        xyz="0 0 0"
        rpy="0 0 0" />
      <geometry>
        <mesh
          filename="package://ultron2_urdf_g/meshes/link5.STL" />
      </geometry>
    </collision>
  </link>
  <joint
    name="joint5"
    type="revolute">
    <origin
      xyz="0.0935 -0.03125 0"
      rpy="3.1416 0 0" />
    <parent
      link="link4" />
    <child
      link="link5" />
    <axis
      xyz="1 0 0" />
    <limit
      lower="-10"
      upper="10"
      effort="100"
      velocity="1000" />
  </joint>
  <link
    name="link6">
    <inertial>
      <origin
        xyz="1.10949256227344E-05 -0.033640150156021 -0.000878339013793139"
        rpy="0 0 0" />
      <mass
        value="0.369986281234796" />
      <inertia
        ixx="0.00015"
        ixy="0.00000"
        ixz="0.00000"
        iyy="0.00013"
        iyz="0.00000"
        izz="0.00018" />
    </inertial>
    <visual>
      <origin
        xyz="0 0 0"
        rpy="0 0 0" />
      <geometry>
        <mesh
          filename="package://ultron2_urdf_g/meshes/link6.STL" />
      </geometry>
      <material
        name="">
        <color
          rgba="0.752941176470588 0.752941176470588 0.752941176470588 1" />
      </material>
    </visual>
    <collision>
      <origin
        xyz="0 0 0"
        rpy="0 0 0" />
      <geometry>
        <mesh
          filename="package://ultron2_urdf_g/meshes/link6.STL" />
      </geometry>
    </collision>
  </link>
  <joint
    name="joint6"
    type="revolute">
    <origin
      xyz="0.1615 -0.03425 0"
      rpy="-3.1416 0 0" />
    <parent
      link="link5" />
    <child
      link="link6" />
    <axis
      xyz="0 1 0" />
    <limit
      lower="-10"
      upper="10"
      effort="100"
      velocity="1000" />
  </joint>
  <link
    name="link7">
    <inertial>
      <origin
        xyz="0.028887 -3.3704E-11 0.0059479"
        rpy="0 0 0" />
      <mass
        value="0.66" />
      <inertia
        ixx="0.00003"
        ixy="0.00000"
        ixz="0.00002"
        iyy="0.00005"
        iyz="0.00000"
        izz="0.00004" />
    </inertial>
    <visual>
      <origin
        xyz="0 0 0"
        rpy="0 0 0" />
      <geometry>
        <mesh
          filename="package://ultron2_urdf_g/meshes/link7.STL" />
      </geometry>
      <material
        name="">
        <color
          rgba="0.89804 0.91765 0.92941 1" />
      </material>
    </visual>
    <collision>
      <origin
        xyz="0 0 0"
        rpy="0 0 0" />
      <geometry>
        <mesh
          filename="package://ultron2_urdf_g/meshes/link7.STL" />
      </geometry>
    </collision>
  </link>
  <joint
    name="joint7"
    type="revolute">
    <origin
      xyz="0 -0.03425 0.022"
      rpy="-3.1416 0 0" />
    <parent
      link="link6" />
    <child
      link="link7" />
    <axis
      xyz="0 0 -1" />
    <limit
      lower="-10"
      upper="10"
      effort="100"
      velocity="1000" />
  </joint>
   <link name="eef_link">
    <inertial>
        <mass value="0.0"/>
        <origin xyz="0.0 0.0 0.0"  rpy="0 0 0"/>
        <inertia ixx="0.0" ixy="0.0" ixz="0.0" iyy="0.0" iyz="0.0" izz="0.0"/>
    </inertial>
    </link>

    <joint name="gripper_fixed_joint" type="fixed">
        <origin xyz="0.145 0.0 0.0" rpy="0 0 0"/>
        <parent link="link7"/>
        <child link="eef_link"/>
    </joint>
</robot>